{"data": "Traceback (most recent call last):\n  File \"/Users/akrah/Documents/dev/SemEval22/clozetask/utils/zlog.py\", line 39, in log_context\n    yield self\n  File \"/Users/akrah/Documents/dev/SemEval22/clozetask/management/runscript.py\", line 169, in run_loop\n    metarunner.run_train_loop()\n  File \"/Users/akrah/Documents/dev/SemEval22/clozetask/shared/metarunner.py\", line 38, in run_train_loop\n    for _ in self.yield_train_step():\n  File \"/Users/akrah/Documents/dev/SemEval22/clozetask/management/metarunner.py\", line 106, in yield_train_step\n    for train_state in train_iterator:\n  File \"/Users/akrah/Documents/dev/SemEval22/clozetask/management/runner.py\", line 74, in run_train_context\n    self.run_train_step(\n  File \"/Users/akrah/Documents/dev/SemEval22/clozetask/management/runner.py\", line 103, in run_train_step\n    model_output = wrap_task_forward(\nTypeError: wrap_task_forward() got an unexpected keyword argument 'jiant_model'\n", "TIMESTAMP": 1638133895.366682}
